Workbook

Sheet Port_NASDAQ
A1: Portfolio of Companies | B1: Ticker | C1: Sector | D1: Industry
A2: Zenas BioPharma, Inc. | B2: ZBIO | C2: Health Care | D2: Biotechnology: Pharmaceutical Preparations
A3: Zillow Group, Inc. | B3: Z | C3: Real Estate | D3: Real Estate
A4: Zebra Technologies Corporation | B4: ZBRA | C4: Industrials | D4: Industrial Machinery/Components
A5: Zions Bancorporation, National Association | B5: ZION | C5: Finance | D5: Major Banks
A6: HIVE Digital Technologies Ltd. | B6: HIVE | C6: Finance | D6: Finance: Consumer Services
A7: Hut 8 Corp. | B7: HUT | C7: Finance | D7: Finance: Consumer Services
A8: Cadence Design Systems, Inc. | B8: CDNS | C8: Technology | D8: Computer Software: Prepackaged Software
A9: CSX Corporation | B9: CSX | C9: Industrials | D9: Railroads

Sheet ZBIO
A1: Date | B1: Volume | C1: TD | D1: CP | E1: SMA5 | F1: BSR
A2: 45817 | B2: 184400 | C2: 1 | D2: 11.92 | F2: {=SUMPRODUCT(--(D7:D39>E7:E39))/33} -> 0.66666667
A3: 45818 | B3: 190700 | C3: 2 | D3: 11.94
A4: 45819 | B4: 1080700 | C4: 3 | D4: 12.11
A5: 45820 | B5: 88800 | C5: 4 | D5: 11.32
A6: 45821 | B6: 172800 | C6: 5 | D6: 10.33
A7: 45824 | B7: 137600 | C7: 6 | D7: 9.97 | E7: =AVERAGE(D2:D6) -> 11.524
A8: 45825 | B8: 176000 | C8: 7 | D8: 9.68 | E8: =AVERAGE(D3:D7) -> 11.134
A9: 45826 | B9: 130900 | C9: 8 | D9: 9.31 | E9: =AVERAGE(D4:D8) -> 10.682
A10: 45828 | B10: 180100 | C10: 9 | D10: 9.19 | E10: =AVERAGE(D5:D9) -> 10.122
A11: 45831 | B11: 113700 | C11: 10 | D11: 9.47 | E11: =AVERAGE(D6:D10) -> 9.696
A12: 45832 | B12: 179900 | C12: 11 | D12: 10.02 | E12: =AVERAGE(D7:D11) -> 9.524
A13: 45833 | B13: 121000 | C13: 12 | D13: 10.19 | E13: =AVERAGE(D8:D12) -> 9.534
A14: 45834 | B14: 145400 | C14: 13 | D14: 10.15 | E14: =AVERAGE(D9:D13) -> 9.636
A15: 45835 | B15: 489000 | C15: 14 | D15: 9.58 | E15: =AVERAGE(D10:D14) -> 9.804
A16: 45838 | B16: 165500 | C16: 15 | D16: 9.69 | E16: =AVERAGE(D11:D15) -> 9.882
A17: 45839 | B17: 260100 | C17: 16 | D17: 9.14 | E17: =AVERAGE(D12:D16) -> 9.926
A18: 45840 | B18: 194400 | C18: 17 | D18: 10.22 | E18: =AVERAGE(D13:D17) -> 9.75
... A39: 45870 | B39: 164600 | C39: 38 | D39: 15.41 | E39: =AVERAGE(D34:D38) -> 15.924
A42: CP=8.6539+0.1749*TD
A44: SUMMARY OUTPUT
A46: Regression Statistics
A47: Multiple R | B47: 0.7956975
A48: R Square | B48: 0.63313452
A49: Adjusted R Square | B49: 0.62294381
A50: Standard Error | B50: 1.5003015
A51: Observations | B51: 38
A53: ANOVA
B54: df | C54: SS | D54: MS | E54: F | F54: Significance F
A55: Regression | B55: 1 | C55: 139.84558 | D55: 139.84558 | E55: 62.12861 | F55: 2.3700035e-09
A56: Residual | B56: 36 | C56: 81.032569 | D56: 2.2509047
A57: Total | B57: 37 | C57: 220.87815
B59: Coefficients | C59: Standard Error | D59: t Stat | E59: P-value | F59: Lower 95% | G59: Upper 95% | H59: Lower 95.0% | I59: Upper 95.0%
A60: Intercept | B60: 8.653926 | C60: 0.49653087 | D60: 17.428778 | E60: 3.9449472e-19 | F60: 7.6469148 | G60: 9.6609373 | H60: 7.6469148 | I60: 9.6609373
A61: TD | B61: 0.17494037 | C61: 0.022194441 | D61: 7.8821704 | E61: 2.3700035e-09 | F61: 0.12992795 | G61: 0.21995278 | H61: 0.12992795 | I61: 0.21995278
A65: RESIDUAL OUTPUT
A67: Observation | B67: Predicted CP | C67: Residuals | D67: Standard Residuals
A68: 1 | B68: 8.8288664 | C68: 3.0911336 | D68: 2.0887614
A69: 2 | B69: 9.0038068 | C69: 2.9361932 | D69: 1.9840641
A70: 3 | B70: 9.1787471 | C70: 2.9312529 | D70: 1.9807257
...

Sheet Z
A1: Date | B1: Volume | C1: TD | D1: CP | E1: SMA5 | F1: BSR
A2: 45817 | B2: 1256200 | C2: 1 | D2: 70.28 | F2: {=SUMPRODUCT(--(D7:D39>E7:E39))/33} -> 0.60606061
A3: 45818 | B3: 1408100 | C3: 2 | D3: 71.51
A4: 45819 | B4: 1838200 | C4: 3 | D4: 71.12
A5: 45820 | B5: 1499000 | C5: 4 | D5: 71.77
A6: 45821 | B6: 1707800 | C6: 5 | D6: 70.37
A7: 45824 | B7: 1090200 | C7: 6 | D7: 70.94 | E7: =AVERAGE(D2:D6) -> 71.01
A8: 45825 | B8: 2628100 | C8: 7 | D8: 67.63 | E8: =AVERAGE(D3:D7) -> 71.142
A9: 45826 | B9: 1441200 | C9: 8 | D9: 67.53 | E9: =AVERAGE(D4:D8) -> 70.366
A10: 45828 | B10: 1733700 | C10: 9 | D10: 68.24 | E10: =AVERAGE(D5:D9) -> 69.648
A11: 45831 | B11: 1713500 | C11: 10 | D11: 69.06 | E11: =AVERAGE(D6:D10) -> 68.942
A12: 45832 | B12: 1718800 | C12: 11 | D12: 70.22 | E12: =AVERAGE(D7:D11) -> 68.68
A13: 45833 | B13: 1281400 | C13: 12 | D13: 68.45 | E13: =AVERAGE(D8:D12) -> 68.536
A14: 45834 | B14: 1340600 | C14: 13 | D14: 69.22 | E14: =AVERAGE(D9:D13) -> 68.7
A15: 45835 | B15: 1355800 | C15: 14 | D15: 69.74 | E15: =AVERAGE(D10:D14) -> 69.038
A16: 45838 | B16: 1894500 | C16: 15 | D16: 70.05 | E16: =AVERAGE(D11:D15) -> 69.338
A17: 45839 | B17: 3513100 | C17: 16 | D17: 71.5 | E17: =AVERAGE(D12:D16) -> 69.536
A18: 45840 | B18: 2039900 | C18: 17 | D18: 71 | E18: =AVERAGE(D13:D17) -> 69.792
... A39: 45870 | B39: 2186900 | C39: 38 | D39: 80.2 | E39: =AVERAGE(D34:D38) -> 80.28
A42: CP=67.1023+0.3734*TD
A44: SUMMARY OUTPUT
A46: Regression Statistics
A47: Multiple R | B47: 0.89363958
A48: R Square | B48: 0.7985917
A49: Adjusted R Square | B49: 0.79299703
A50: Standard Error | B50: 2.1128516
A51: Observations | B51: 38
A53: ANOVA
B54: df | C54: SS | D54: MS | E54: F | F54: Significance F
A55: Regression | B55: 1 | C55: 637.21782 | D55: 637.21782 | E55: 142.74139 | F55: 4.3668141e-14
A56: Residual | B56: 36 | C56: 160.70911 | D56: 4.4641418
A57: Total | B57: 37 | C57: 797.92693
B59: Coefficients | C59: Standard Error | D59: t Stat | E59: P-value | F59: Lower 95% | G59: Upper 95% | H59: Lower 95.0% | I59: Upper 95.0%
A60: Intercept | B60: 67.102319 | C60: 0.69925679 | D60: 95.962341 | E60: 5.6090597e-45 | F60: 65.68416 | G60: 68.520477 | H60: 65.68416 | I60: 68.520477
A61: TD | B61: 0.37343035 | C61: 0.03125609 | D61: 11.947443 | E61: 4.3668141e-14 | F61: 0.31004006 | G61: 0.43682064 | H61: 0.31004006 | I61: 0.43682064
A65: RESIDUAL OUTPUT
A67: Observation | B67: Predicted CP | C67: Residuals | D67: Standard Residuals
A68: 1 | B68: 67.475749 | C68: 2.804251 | D68: 1.3455428
A69: 2 | B69: 67.849179 | C69: 3.6608207 | D69: 1.7565442
A70: 3 | B70: 68.22261 | C70: 2.8973903 | D70: 1.3902331
...

Sheet ZBRA
A1: Date | B1: Volume | C1: TD | D1: CP | E1: SMA5 | F1: BSR
A2: 45817 | B2: 341700 | C2: 1 | D2: 298.63 | F2: {=SUMPRODUCT(--(D7:D39>E7:E39))/33} -> 0.78787879
A3: 45818 | B3: 398500 | C3: 2 | D3: 299.56
A4: 45819 | B4: 384200 | C4: 3 | D4: 292.82
A5: 45820 | B5: 295900 | C5: 4 | D5: 292.68
A6: 45821 | B6: 309700 | C6: 5 | D6: 283.61
A7: 45824 | B7: 379000 | C7: 6 | D7: 293.06 | E7: =AVERAGE(D2:D6) -> 293.46
A8: 45825 | B8: 570200 | C8: 7 | D8: 289.36 | E8: =AVERAGE(D3:D7) -> 292.346
A9: 45826 | B9: 571200 | C9: 8 | D9: 291.73 | E9: =AVERAGE(D4:D8) -> 290.306
A10: 45828 | B10: 777900 | C10: 9 | D10: 294.04 | E10: =AVERAGE(D5:D9) -> 290.088
A11: 45831 | B11: 411700 | C11: 10 | D11: 296.25 | E11: =AVERAGE(D6:D10) -> 290.36
A12: 45832 | B12: 541600 | C12: 11 | D12: 298.94 | E12: =AVERAGE(D7:D11) -> 292.888
A13: 45833 | B13: 284900 | C13: 12 | D13: 303.05 | E13: =AVERAGE(D8:D12) -> 294.064
A14: 45834 | B14: 443200 | C14: 13 | D14: 308.32 | E14: =AVERAGE(D9:D13) -> 296.802
A15: 45835 | B15: 893900 | C15: 14 | D15: 309.26 | E15: =AVERAGE(D10:D14) -> 300.12
A16: 45838 | B16: 783800 | C16: 15 | D16: 308.36 | E16: =AVERAGE(D11:D15) -> 303.164
A17: 45839 | B17: 452000 | C17: 16 | D17: 315.48 | E17: =AVERAGE(D12:D16) -> 305.586
A18: 45840 | B18: 428800 | C18: 17 | D18: 320.39 | E18: =AVERAGE(D13:D17) -> 308.894
... A39: 45870 | B39: 976400 | C39: 38 | D39: 335.24 | E39: =AVERAGE(D34:D38) -> 334.678
A42: CP=288.3619+1.4031*TD
A44: SUMMARY OUTPUT
A46: Regression Statistics
A47: Multiple R | B47: 0.9388301
A48: R Square | B48: 0.88140196
A49: Adjusted R Square | B49: 0.87810757
A50: Standard Error | B50: 5.7986717
A51: Observations | B51: 38
A53: ANOVA
B54: df | C54: SS | D54: MS | E54: F | F54: Significance F
A55: Regression | B55: 1 | C55: 8996.1364 | D55: 8996.1364 | E55: 267.54632 | F55: 3.0203442e-18
A56: Residual | B56: 36 | C56: 1210.4854 | D56: 33.624593
A57: Total | B57: 37 | C57: 10206.622
B59: Coefficients | C59: Standard Error | D59: t Stat | E59: P-value | F59: Lower 95% | G59: Upper 95% | H59: Lower 95.0% | I59: Upper 95.0%
A60: Intercept | B60: 288.36186 | C60: 1.9190939 | D60: 150.25938 | E60: 5.698935e-52 | F60: 284.46976 | G60: 292.25397 | H60: 284.46976 | I60: 292.25397
A61: TD | B61: 1.4031163 | C61: 0.085781607 | D61: 16.356843 | E61: 3.0203442e-18 | F61: 1.2291432 | G61: 1.5770895 | H61: 1.2291432 | I61: 1.5770895
A65: RESIDUAL OUTPUT
A67: Observation | B67: Predicted CP | C67: Residuals | D67: Standard Residuals
A68: 1 | B68: 289.76498 | C68: 8.8650202 | D68: 1.5498898
A69: 2 | B69: 291.1681 | C69: 8.3919039 | D69: 1.4671739
A70: 3 | B70: 292.57121 | C70: 0.24878761 | D70: 0.043496053
...

Sheet ZION
A1: Date | B1: Volume | C1: TD | D1: CP | E1: SMA5 | F1: BSR
A2: 45817 | B2: 887300 | C2: 1 | D2: 49.3 | F2: {=SUMPRODUCT(--(D7:D39>E7:E39))/33} -> 0.66666667
A3: 45818 | B3: 934600 | C3: 2 | D3: 49.8
A4: 45819 | B4: 1500200 | C4: 3 | D4: 48.91
A5: 45820 | B5: 987400 | C5: 4 | D5: 48.72
A6: 45821 | B6: 1093100 | C6: 5 | D6: 47.43
A7: 45824 | B7: 1119900 | C7: 6 | D7: 47.85 | E7: =AVERAGE(D2:D6) -> 48.832
A8: 45825 | B8: 1590500 | C8: 7 | D8: 47.28 | E8: =AVERAGE(D3:D7) -> 48.542
A9: 45826 | B9: 1601600 | C9: 8 | D9: 48.33 | E9: =AVERAGE(D4:D8) -> 48.038
A10: 45828 | B10: 1483700 | C10: 9 | D10: 48.58 | E10: =AVERAGE(D5:D9) -> 47.922
A11: 45831 | B11: 1208000 | C11: 10 | D11: 49.47 | E11: =AVERAGE(D6:D10) -> 47.894
A12: 45832 | B12: 986000 | C12: 11 | D12: 50.09 | E12: =AVERAGE(D7:D11) -> 48.302
A13: 45833 | B13: 662900 | C13: 12 | D13: 50.13 | E13: =AVERAGE(D8:D12) -> 48.75
A14: 45834 | B14: 1021900 | C14: 13 | D14: 51.4 | E14: =AVERAGE(D9:D13) -> 49.32
A15: 45835 | B15: 1556900 | C15: 14 | D15: 51.47 | E15: =AVERAGE(D10:D14) -> 49.934
A16: 45838 | B16: 1174800 | C16: 15 | D16: 51.94 | E16: =AVERAGE(D11:D15) -> 50.512
A17: 45839 | B17: 1965200 | C17: 16 | D17: 53.75 | E17: =AVERAGE(D12:D16) -> 51.006
A18: 45840 | B18: 1421100 | C18: 17 | D18: 54.77 | E18: =AVERAGE(D13:D17) -> 51.738
... A39: 45870 | B39: 1451100 | C39: 38 | D39: 52.08 | E39: =AVERAGE(D34:D38) -> 54.668
A42: CP=48.5426+0.2285*TD
A44: SUMMARY OUTPUT
A46: Regression Statistics
A47: Multiple R | B47: 0.78685151
A48: R Square | B48: 0.61913531
A49: Adjusted R Square | B49: 0.60855573
A50: Standard Error | B50: 2.0190303
A51: Observations | B51: 38
A53: ANOVA
B54: df | C54: SS | D54: MS | E54: F | F54: Significance F
A55: Regression | B55: 1 | C55: 238.56297 | D55: 238.56297 | E55: 58.521757 | F55: 4.698648e-09
A56: Residual | B56: 36 | C56: 146.7534 | D56: 4.0764834
A57: Total | B57: 37 | C57: 385.31637
B59: Coefficients | C59: Standard Error | D59: t Stat | E59: P-value | F59: Lower 95% | G59: Upper 95% | H59: Lower 95.0% | I59: Upper 95.0%
A60: Intercept | B60: 48.542603 | C60: 0.66820626 | D60: 72.646137 | E60: 1.1990061e-40 | F60: 47.187418 | G60: 49.897788 | H60: 47.187418 | I60: 49.897788
A61: TD | B61: 0.22848999 | C61: 0.029868162 | D61: 7.6499514 | E61: 4.698648e-09 | F61: 0.16791455 | G61: 0.28906543 | H61: 0.16791455 | I61: 0.28906543
A65: RESIDUAL OUTPUT
A67: Observation | B67: Predicted CP | C67: Residuals | D67: Standard Residuals
A68: 1 | B68: 48.771093 | C68: 0.52890688 | D68: 0.26557427
A69: 2 | B69: 48.999583 | C69: 0.80041689 | D69: 0.40190464
A70: 3 | B70: 49.228073 | C70: -0.31807309 | D70: -0.15971059
...

Sheet HIVE
A1: Date | B1: Volume | C1: TD | D1: CP | E1: SMA5 | F1: BSR
A2: 45817 | B2: 14261000 | C2: 1 | D2: 2.01 | F2: {=SUMPRODUCT(--(D7:D39>E7:E39))/33} -> 0.51515152
A3: 45818 | B3: 18445200 | C3: 2 | D3: 2.02
A4: 45819 | B4: 17159300 | C4: 3 | D4: 2
A5: 45820 | B5: 17348200 | C5: 4 | D5: 1.95
A6: 45821 | B6: 16016100 | C6: 5 | D6: 1.89
A7: 45824 | B7: 18221000 | C7: 6 | D7: 1.9 | E7: =AVERAGE(D2:D6) -> 1.974
A8: 45825 | B8: 12196800 | C8: 7 | D8: 1.76 | E8: =AVERAGE(D3:D7) -> 1.952
A9: 45826 | B9: 15642800 | C9: 8 | D9: 1.76 | E9: =AVERAGE(D4:D8) -> 1.9
A10: 45828 | B10: 24899800 | C10: 9 | D10: 1.7 | E10: =AVERAGE(D5:D9) -> 1.852
A11: 45831 | B11: 18031900 | C11: 10 | D11: 1.67 | E11: =AVERAGE(D6:D10) -> 1.802
A12: 45832 | B12: 19494600 | C12: 11 | D12: 1.85 | E12: =AVERAGE(D7:D11) -> 1.758
A13: 45833 | B13: 18746900 | C13: 12 | D13: 1.78 | E13: =AVERAGE(D8:D12) -> 1.748
A14: 45834 | B14: 28654200 | C14: 13 | D14: 1.79 | E14: =AVERAGE(D9:D13) -> 1.752
A15: 45835 | B15: 28373700 | C15: 14 | D15: 1.8 | E15: =AVERAGE(D10:D14) -> 1.758
A16: 45838 | B16: 32054600 | C16: 15 | D16: 1.8 | E16: =AVERAGE(D11:D15) -> 1.778
A17: 45839 | B17: 33289300 | C17: 16 | D17: 2.07 | E17: =AVERAGE(D12:D16) -> 1.804
A18: 45840 | B18: 51681300 | C18: 17 | D18: 2.25 | E18: =AVERAGE(D13:D17) -> 1.848
... A39: 45870 | B39: 32909700 | C39: 38 | D39: 2.03 | E39: =AVERAGE(D34:D38) -> 2.194
A42: CP=1.8231+0.0135*TD
A44: SUMMARY OUTPUT
A46: Regression Statistics
A47: Multiple R | B47: 0.67151975
A48: R Square | B48: 0.45093878
A49: Adjusted R Square | B49: 0.43568708
A50: Standard Error | B50: 0.16745344
A51: Observations | B51: 38
A53: ANOVA
B54: df | C54: SS | D54: MS | E54: F | F54: Significance F
A55: Regression | B55: 1 | C55: 0.82906281 | D55: 0.82906281 | E55: 29.566459 | F55: 3.9255081e-06
A56: Residual | B56: 36 | C56: 1.0094635 | D56: 0.028040653
A57: Total | B57: 37 | C57: 1.8385263
B59: Coefficients | C59: Standard Error | D59: t Stat | E59: P-value | F59: Lower 95% | G59: Upper 95% | H59: Lower 95.0% | I59: Upper 95.0%
A60: Intercept | B60: 1.8231294 | C60: 0.055419393 | D60: 32.896958 | E60: 1.8515057e-28 | F60: 1.7107337 | G60: 1.9355252 | H60: 1.7107337 | I60: 1.9355252
A61: TD | B61: 0.013469745 | C61: 0.0024771923 | D61: 5.4375048 | E61: 3.9255081e-06 | F61: 0.0084457662 | G61: 0.018493724 | H61: 0.0084457662 | I61: 0.018493724
A65: RESIDUAL OUTPUT
A67: Observation | B67: Predicted CP | C67: Residuals | D67: Standard Residuals
A68: 1 | B68: 1.8365992 | C68: 0.17340081 | D68: 1.0498002
A69: 2 | B69: 1.8500689 | C69: 0.16993106 | D69: 1.0287938
A70: 3 | B70: 1.8635387 | C70: 0.13646132 | D70: 0.82616181
...

Sheet HUT
A1: Date | B1: Volume | C1: TD | D1: CP | E1: SMA5 | F1: BSR
A2: 45817 | B2: 5962900 | C2: 1 | D2: 18.55 | F2: {=SUMPRODUCT(--(D7:D39>E7:E39))/33} -> 0.54545455
A3: 45818 | B3: 4384100 | C3: 2 | D3: 18.53
A4: 45819 | B4: 4598300 | C4: 3 | D4: 18.52
A5: 45820 | B5: 4028900 | C5: 4 | D5: 18.36
A6: 45821 | B6: 4831600 | C6: 5 | D6: 17.48
A7: 45824 | B7: 4489900 | C7: 6 | D7: 18.46 | E7: =AVERAGE(D2:D6) -> 18.288
A8: 45825 | B8: 5327900 | C8: 7 | D8: 16.99 | E8: =AVERAGE(D3:D7) -> 18.27
A9: 45826 | B9: 5691400 | C9: 8 | D9: 17.03 | E9: =AVERAGE(D4:D8) -> 17.962
A10: 45828 | B10: 6626000 | C10: 9 | D10: 16.7 | E10: =AVERAGE(D5:D9) -> 17.664
A11: 45831 | B11: 7321400 | C11: 10 | D11: 15.89 | E11: =AVERAGE(D6:D10) -> 17.332
A12: 45832 | B12: 5097300 | C12: 11 | D12: 17.24 | E12: =AVERAGE(D7:D11) -> 17.014
A13: 45833 | B13: 6721900 | C13: 12 | D13: 17.45 | E13: =AVERAGE(D8:D12) -> 16.77
A14: 45834 | B14: 9417100 | C14: 13 | D14: 18.68 | E14: =AVERAGE(D9:D13) -> 16.862
A15: 45835 | B15: 7735000 | C15: 14 | D15: 17.66 | E15: =AVERAGE(D10:D14) -> 17.192
A16: 45838 | B16: 5177000 | C16: 15 | D16: 18.6 | E16: =AVERAGE(D11:D15) -> 17.384
A17: 45839 | B17: 6178500 | C17: 16 | D17: 18.48 | E17: =AVERAGE(D12:D16) -> 17.926
A18: 45840 | B18: 16981400 | C18: 17 | D18: 21.08 | E18: =AVERAGE(D13:D17) -> 18.174
... A39: 45870 | B39: 4766500 | C39: 38 | D39: 19.78 | E39: =AVERAGE(D34:D38) -> 20.292
A42: CP=17.5031+0.1163*TD
A44: SUMMARY OUTPUT | M44: =41299/35215-1 -> 0.17276729
A46: Regression Statistics
A47: Multiple R | B47: 0.68375497
A48: R Square | B48: 0.46752085
A49: Adjusted R Square | B49: 0.45272977
A50: Standard Error | B50: 1.3982168
A51: Observations | B51: 38
A53: ANOVA
B54: df | C54: SS | D54: MS | E54: F | F54: Significance F
A55: Regression | B55: 1 | C55: 61.794511 | D55: 61.794511 | E55: 31.608282 | F55: 2.2239071e-06
A56: Residual | B56: 36 | C56: 70.380365 | D56: 1.9550101
A57: Total | B57: 37 | C57: 132.17488
B59: Coefficients | C59: Standard Error | D59: t Stat | E59: P-value | F59: Lower 95% | G59: Upper 95% | H59: Lower 95.0% | I59: Upper 95.0%
A60: Intercept | B60: 17.503144 | C60: 0.4627455 | D60: 37.824557 | E60: 1.3970105e-30 | F60: 16.564652 | G60: 18.441635 | H60: 16.564652 | I60: 18.441635
A61: TD | B61: 0.11628953 | C61: 0.020684269 | D61: 5.6221243 | E61: 2.2239071e-06 | F61: 0.074339888 | G61: 0.15823917 | H61: 0.074339888 | I61: 0.15823917
A65: RESIDUAL OUTPUT
A67: Observation | B67: Predicted CP | C67: Residuals | D67: Standard Residuals
A68: 1 | B68: 17.619433 | C68: 0.9305668 | D68: 0.67471856
A69: 2 | B69: 17.735723 | C69: 0.79427727 | D69: 0.57590021
A70: 3 | B70: 17.852012 | C70: 0.66798774 | D70: 0.48433248
...

Sheet CDNS
A1: Date | B1: Volume | C1: TD | D1: CP | E1: SMA5 | F1: BSR
A2: 45817 | B2: 2517000 | C2: 1 | D2: 301.66 | F2: {=SUMPRODUCT(--(D7:D39>E7:E39))/33} -> 0.63636364
A3: 45818 | B3: 1603300 | C3: 2 | D3: 305.69
A4: 45819 | B4: 1259400 | C4: 3 | D4: 307.2
A5: 45820 | B5: 1012800 | C5: 4 | D5: 307.85
A6: 45821 | B6: 1188800 | C6: 5 | D6: 300
A7: 45824 | B7: 1697100 | C7: 6 | D7: 300.81 | E7: =AVERAGE(D2:D6) -> 304.48
A8: 45825 | B8: 1130400 | C8: 7 | D8: 299 | E8: =AVERAGE(D3:D7) -> 304.31
A9: 45826 | B9: 1221000 | C9: 8 | D9: 296.84 | E9: =AVERAGE(D4:D8) -> 302.972
A10: 45828 | B10: 2373300 | C10: 9 | D10: 295.4 | E10: =AVERAGE(D5:D9) -> 300.9
A11: 45831 | B11: 2134500 | C11: 10 | D11: 293.56 | E11: =AVERAGE(D6:D10) -> 298.41
A12: 45832 | B12: 1906300 | C12: 11 | D12: 296.8 | E12: =AVERAGE(D7:D11) -> 297.122
A13: 45833 | B13: 1736800 | C13: 12 | D13: 297.53 | E13: =AVERAGE(D8:D12) -> 296.32
A14: 45834 | B14: 2128200 | C14: 13 | D14: 303.69 | E14: =AVERAGE(D9:D13) -> 296.026
A15: 45835 | B15: 2331800 | C15: 14 | D15: 305.2 | E15: =AVERAGE(D10:D14) -> 297.396
A16: 45838 | B16: 1748300 | C16: 15 | D16: 308.15 | E16: =AVERAGE(D11:D15) -> 299.356
A17: 45839 | B17: 1332100 | C17: 16 | D17: 309.46 | E17: =AVERAGE(D12:D16) -> 302.274
A18: 45840 | B18: 1164600 | C18: 17 | D18: 310.95 | E18: =AVERAGE(D13:D17) -> 304.806
... A39: 45870 | B39: 2070000 | C39: 38 | D39: 356.97 | E39: =AVERAGE(D34:D38) -> 353.562
A42: CP=289.4251+1.4528*TD
A44: SUMMARY OUTPUT
A46: Regression Statistics
A47: Multiple R | B47: 0.82362428
A48: R Square | B48: 0.67835695
A49: Adjusted R Square | B49: 0.66942242
A50: Standard Error | B50: 11.270724
A51: Observations | B51: 38
A53: ANOVA
B54: df | C54: SS | D54: MS | E54: F | F54: Significance F
A55: Regression | B55: 1 | C55: 9644.733 | D55: 9644.733 | E55: 75.925317 | F55: 2.1503589e-10
A56: Residual | B56: 36 | C56: 4573.0516 | D56: 127.02921
A57: Total | B57: 37 | C57: 14217.785
B59: Coefficients | C59: Standard Error | D59: t Stat | E59: P-value | F59: Lower 95% | G59: Upper 95% | H59: Lower 95.0% | I59: Upper 95.0%
A60: Intercept | B60: 289.42508 | C60: 3.7300916 | D60: 77.591949 | E60: 1.1361611e-41 | F60: 281.8601 | G60: 296.99005 | H60: 281.8601 | I60: 296.99005
A61: TD | B61: 1.4528165 | C61: 0.16673142 | D61: 8.7135135 | E61: 2.1503589e-10 | F61: 1.1146695 | G61: 1.7909635 | H61: 1.1146695 | I61: 1.7909635
A65: RESIDUAL OUTPUT
A67: Observation | B67: Predicted CP | C67: Residuals | D67: Standard Residuals
A68: 1 | B68: 290.87789 | C68: 10.782105 | D68: 0.96984288
A69: 2 | B69: 292.33071 | C69: 13.359289 | D69: 1.2016587
A70: 3 | B70: 293.78353 | C70: 13.416472 | D70: 1.2068024
...

Sheet CSX
A1: Date | B1: Volume | C1: TD | D1: CP | E1: SMA5 | F1: BSR
A2: 45817 | B2: 14841700 | C2: 1 | D2: 31.98 | F2: {=SUMPRODUCT(--(D7:D39>E7:E39))/33} -> 0.72727273
A3: 45818 | B3: 24562700 | C3: 2 | D3: 32.61
A4: 45819 | B4: 12114200 | C4: 3 | D4: 32.32
A5: 45820 | B5: 9380500 | C5: 4 | D5: 32.39
A6: 45821 | B6: 9032700 | C6: 5 | D6: 32.12
A7: 45824 | B7: 11703600 | C7: 6 | D7: 32.56 | E7: =AVERAGE(D2:D6) -> 32.284
A8: 45825 | B8: 12951300 | C8: 7 | D8: 32.12 | E8: =AVERAGE(D3:D7) -> 32.4
A9: 45826 | B9: 12808100 | C9: 8 | D9: 32.24 | E9: =AVERAGE(D4:D8) -> 32.302
A10: 45828 | B10: 31011100 | C10: 9 | D10: 32.06 | E10: =AVERAGE(D5:D9) -> 32.286
A11: 45831 | B11: 12350200 | C11: 10 | D11: 32.42 | E11: =AVERAGE(D6:D10) -> 32.22
A12: 45832 | B12: 12913900 | C12: 11 | D12: 32.48 | E12: =AVERAGE(D7:D11) -> 32.28
A13: 45833 | B13: 11235100 | C13: 12 | D13: 32.49 | E13: =AVERAGE(D8:D12) -> 32.264
A14: 45834 | B14: 12447700 | C14: 13 | D14: 32.57 | E14: =AVERAGE(D9:D13) -> 32.338
A15: 45835 | B15: 20445500 | C15: 14 | D15: 32.91 | E15: =AVERAGE(D10:D14) -> 32.404
A16: 45838 | B16: 12112500 | C16: 15 | D16: 32.63 | E16: =AVERAGE(D11:D15) -> 32.574
A17: 45839 | B17: 12862800 | C17: 16 | D17: 33.47 | E17: =AVERAGE(D12:D16) -> 32.616
A18: 45840 | B18: 8596900 | C18: 17 | D18: 33.61 | E18: =AVERAGE(D13:D17) -> 32.814
... A39: 45870 | B39: 19266500 | C39: 38 | D39: 35.01 | E39: =AVERAGE(D34:D38) -> 35.544
A42: CP=31.5940+0.1016*TD
A44: SUMMARY OUTPUT
A46: Regression Statistics
A47: Multiple R | B47: 0.94172936
A48: R Square | B48: 0.88685418
A49: Adjusted R Square | B49: 0.88371124
A50: Standard Error | B50: 0.40903507
A51: Observations | B51: 38
A53: ANOVA
B54: df | C54: SS | D54: MS | E54: F | F54: Significance F
A55: Regression | B55: 1 | C55: 47.210359 | D55: 47.210359 | E55: 282.1735 | F55: 1.2909024e-18
A56: Residual | B56: 36 | C56: 6.0231487 | D56: 0.16730969
A57: Total | B57: 37 | C57: 53.233508
B59: Coefficients | C59: Standard Error | D59: t Stat | E59: P-value | F59: Lower 95% | G59: Upper 95% | H59: Lower 95.0% | I59: Upper 95.0%
A60: Intercept | B60: 31.593983 | C60: 0.13537181 | D60: 233.38672 | E60: 7.5587221e-59 | F60: 31.319436 | G60: 31.86853 | H60: 31.319436 | I60: 31.86853
A61: TD | B61: 0.1016446 | C61: 0.0060509868 | D61: 16.798021 | E61: 1.2909024e-18 | F61: 0.08937263 | G61: 0.11391657 | H61: 0.08937263 | I61: 0.11391657
A65: RESIDUAL OUTPUT
A67: Observation | B67: Predicted CP | C67: Residuals | D67: Standard Residuals
A68: 1 | B68: 31.695628 | C68: 0.28437247 | D68: 0.7048174
A69: 2 | B69: 31.797272 | C69: 0.81272787 | D69: 2.0143467
A70: 3 | B70: 31.898917 | C70: 0.42108327 | D70: 1.0436552
...

Sheet Optimisation
A1: Ticker | B1: CP | C1: R² | D1: DG | E1: BSR | F1: Days_Invested | G1: Per-Co Cap ($) | H1: Shares (#) | I1: Invested ($) | J1: Expected Return ($) | L1: Port. Cap ($)
A2: ZBIO | B2: =ZBIO!$D$39 -> 15.41 | C2: =ZBIO!$B$48 -> 0.63313452 | D2: =ZBIO!$B$61 -> 0.17494037 | E2: =ZBIO!$F$2 -> 0.66666667 | F2: =_xlfn.CEILING.MATH(E2*10,1) -> 7 | G2: =50000*C2 -> 31656.726 | H2: 2054 | I2: =H2*B2 -> 31652.14 | J2: =H2*D2*F2 -> 2515.2926 | L2: =20000*COUNTA(A2:A9) -> 160000
A3: Z | B3: =Z!$D$39 -> 80.2 | C3: =Z!$B$48 -> 0.7985917 | D3: =Z!$B$61 -> 0.37343035 | E3: =Z!$F$2 -> 0.60606061 | F3: =_xlfn.CEILING.MATH(E3*10,1) -> 7 | G3: =50000*C3 -> 39929.585 | H3: 480 | I3: =H3*B3 -> 38496 | J3: =H3*D3*F3 -> 1254.726
A4: ZBRA | B4: =ZBRA!D39 -> 335.24 | C4: =ZBRA!B48 -> 0.88140196 | D4: =ZBRA!B61 -> 1.4031163 | E4: =ZBRA!F2 -> 0.78787879 | F4: =_xlfn.CEILING.MATH(E4*10,1) -> 8 | G4: =50000*C4 -> 44070.098 | H4: 131 | I4: =H4*B4 -> 43916.44 | J4: =H4*D4*F4 -> 1470.4659
A5: ZION | B5: =ZION!$D$39 -> 52.08 | C5: =ZION!$B$48 -> 0.61913531 | D5: =ZION!$B$61 -> 0.22848999 | E5: =ZION!$F$2 -> 0.66666667 | F5: =_xlfn.CEILING.MATH(E5*10,1) -> 7 | G5: =50000*C5 -> 30956.765 | H5: 1 | I5: =H5*B5 -> 52.08 | J5: =H5*D5*F5 -> 1.5994299
A6: HIVE | B6: =HIVE!D39 -> 2.03 | C6: =HIVE!B48 -> 0.45093878 | D6: =HIVE!B61 -> 0.013469745 | E6: =HIVE!F2 -> 0.51515152 | F6: =_xlfn.CEILING.MATH(E6*10,1) -> 6 | G6: =50000*C6 -> 22546.939 | H6: 11104 | I6: =H6*B6 -> 22541.12 | J6: =H6*D6*F6 -> 897.40829
A7: HUT | B7: =HUT!D39 -> 19.78 | C7: =HUT!B48 -> 0.46752085 | D7: =HUT!B61 -> 0.11628953 | E7: =HUT!F2 -> 0.54545455 | F7: =_xlfn.CEILING.MATH(E7*10,1) -> 6 | G7: =50000*C7 -> 23376.043 | H7: 1180 | I7: =H7*B7 -> 23340.4 | J7: =H7*D7*F7 -> 823.32986
A8: CDNS | B8: =CDNS!D39 -> 356.97 | C8: =CDNS!B48 -> 0.67835695 | D8: =CDNS!B61 -> 1.4528165 | E8: =CDNS!F2 -> 0.63636364 | F8: =_xlfn.CEILING.MATH(E8*10,1) -> 7 | G8: =50000*C8 -> 33917.848 | H8: 0 | I8: =H8*B8 -> 0 | J8: =H8*D8*F8 -> 0
A9: CSX | B9: =CSX!D39 -> 35.01 | C9: =CSX!B48 -> 0.88685418 | D9: =CSX!B61 -> 0.1016446 | E9: =CSX!F2 -> 0.72727273 | F9: =_xlfn.CEILING.MATH(E9*10,1) -> 8 | G9: =50000*C9 -> 44342.709 | H9: 0 | I9: =H9*B9 -> 0 | J9: =H9*D9*F9 -> 0
I11: =SUM(I2:I9) -> 159998.18 | J11: =SUM(J2:J9) -> 6962.822
A14: Ticker | B14: Expected Return ($) | C14: Actual Return ($) | D14: Deviation ($)
A15: ZBIO | B15: 2515.2926 | C15: =(ZBIO!D119-ZBIO!C110)*Optimisation!H2 -> 2464.8 | D15: =C15-B15 -> -50.492575
A16: Z | B16: 1254.726 | C16: =(Z!D119-Z!C110)*Optimisation!H3 -> 1891.2 | D16: =C16-B16 -> 636.47401
A17: ZBRA | B17: 1470.4659 | C17: =(ZBRA!D119-ZBRA!C110)*Optimisation!H4 -> -2614.76 | D17: =C17-B17 -> -4085.2259
A18: ZION | B18: 1.5994299 | C18: =(ZION!D119-ZION!C110)*Optimisation!H5 -> 0.19 | D18: =C18-B18 -> -1.4094299
A19: HIVE | B19: 897.40829 | C19: =(HIVE!D119-HIVE!C110)*Optimisation!H6 -> 1887.68 | D19: =C19-B19 -> 990.27171
A20: HUT | B20: 823.32986 | C20: =(HUT!D119-HUT!C110)*Optimisation!H7 -> 3953 | D20: =C20-B20 -> 3129.6701
A21: CDNS | B21: 0 | C21: =(CDNS!D119-CDNS!C110)*Optimisation!H8 -> 0 | D21: =C21-B21 -> 0
A22: CSX | B22: 0 | C22: =(CSX!D119-CSX!C110)*Optimisation!H9 -> 0 | D22: =C22-B22 -> 0
B24: 6962.822 | C24: =SUM(C15:C22) -> 7582.11 | D24: =C24-B24 -> 619.28795
C25: =C24/B24-1 -> 0.088942091
